<?xml version="1.0" ?>
<robot name="str1ker">
    <!-- Arm links -->
    <link name="base_link">
        <visual>
            <origin rpy="0 0 0" xyz="0 0 0" />
            <geometry>
                <mesh filename="package://str1ker/description/models/ArmBase.stl" />
            </geometry>
            <material name="aluminum">
                <color rgba="1 1 1 1" />
            </material>
        </visual>
        <collision>
            <origin rpy="0 0 0" xyz="0 0 0" />
            <geometry>
                <mesh filename="package://str1ker/description/models/ArmBaseBoundingBox.stl" />
            </geometry>
        </collision>
    </link>
    <link name="shoulder_link">
        <visual>
            <origin rpy="0 0 0" xyz="0 0 0" />
            <geometry>
                <mesh filename="package://str1ker/description/models/Shoulder.stl" />
            </geometry>
            <material name="aluminum">
                <color rgba="1 1 1 1" />
            </material>
        </visual>
        <collision>
            <origin rpy="0 0 0" xyz="0 0 0" />
            <geometry>
                <mesh filename="package://str1ker/description/models/ShoulderBoundingBox.stl" />
            </geometry>
        </collision>
        <inertial>
            <origin rpy="0 0 0" xyz="0 0 0" />
            <mass value="0.36378108" />
            <inertia ixx="0.002" ixy="0" ixz="0" iyy="0.001" iyz="0" izz="0.001" />
        </inertial>
    </link>
    <link name="upperarm_link">
        <visual>
            <origin rpy="0 0 0" xyz="0 0 0" />
            <geometry>
                <mesh filename="package://str1ker/description/models/UpperArm.stl" />
            </geometry>
            <material name="aluminum">
                <color rgba="1 1 1 1" />
            </material>
        </visual>
        <collision>
            <origin rpy="0 0 0" xyz="0 0 0" />
            <geometry>
                <mesh filename="package://str1ker/description/models/UpperArmBoundingBox.stl" />
            </geometry>
        </collision>
        <inertial>
            <origin rpy="0 0 0" xyz="0 0 0" />
            <mass value="1.139" />
            <inertia ixx="0.061" ixy="0" ixz="0" iyy="0.001" iyz="0.001" izz="0.060" />
        </inertial>
    </link>
    <link name="forearm_link">
        <visual>
            <origin rpy="0 0 0" xyz="0 0 0" />
            <geometry>
                <mesh filename="package://str1ker/description/models/Forearm.stl" />
            </geometry>
            <material name="aluminum">
                <color rgba="1 1 1 1" />
            </material>
        </visual>
        <collision>
            <origin rpy="0 0 0" xyz="0 0 0" />
            <geometry>
                <mesh filename="package://str1ker/description/models/ForearmBoundingBox.stl" />
            </geometry>
        </collision>
        <inertial>
            <origin rpy="0 0 0" xyz="0 0 0" />
            <mass value="0.703" />
            <inertia ixx="0.047" ixy="0" ixz="0" iyy="0" iyz="0.001" izz="0.047" />
        </inertial>
    </link>
    <link name="solenoid_mount_link">
        <visual>
            <origin rpy="0 0 0" xyz="0 0 0" />
            <geometry>
                <mesh filename="package://str1ker/description/models/ArmSolenoid.stl" />
            </geometry>
            <material name="aluminum">
                <color rgba="1 1 1 1" />
            </material>
        </visual>
        <collision>
            <origin rpy="0 0 0" xyz="0 0 0" />
            <geometry>
                <mesh filename="package://str1ker/description/models/ArmSolenoidBoundingBox.stl" />
            </geometry>
        </collision>
        <inertial>
            <mass value="0.1" />
            <origin xyz="0 0 0" rpy="0 0 0" />
            <inertia ixx="0.03" iyy="0.03" izz="0.03" ixy="0.0" ixz="0.0" iyz="0.0" />
        </inertial>
    </link>
    <link name="solenoid_shaft_link">
        <visual>
            <origin rpy="0 0 0" xyz="0 0 0" />
            <geometry>
                <mesh filename="package://str1ker/description/models/ArmSolenoidShaft.stl" />
            </geometry>
            <material name="aluminum">
                <color rgba="1 1 1 1" />
            </material>
        </visual>
        <collision>
            <origin rpy="0 0 0" xyz="0 0 0" />
            <geometry>
                <mesh filename="package://str1ker/description/models/ArmSolenoidShaftBoundingBox.stl" />
            </geometry>
        </collision>
        <inertial>
            <mass value="0.1" />
            <origin xyz="0 0 0" rpy="0 0 0" />
            <inertia ixx="0.03" iyy="0.03" izz="0.03" ixy="0.0" ixz="0.0" iyz="0.0" />
        </inertial>
    </link>
    <link name="drumstick_link">
        <visual>
            <origin rpy="0 0 0" xyz="0 0 0" />
            <geometry>
                <mesh filename="package://str1ker/description/models/Drumstick.stl" />
            </geometry>
            <material name="aluminum">
                <color rgba="1 1 1 1" />
            </material>
        </visual>
        <collision>
            <origin rpy="0 0 0" xyz="0 0 0" />
            <geometry>
                <mesh filename="package://str1ker/description/models/DrumstickBoundingBox.stl" />
            </geometry>
        </collision>
        <inertial>
            <origin rpy="0 0 0" xyz="0 0 0" />
            <mass value="0.091" />
            <inertia ixx="0.001" ixy="0" ixz="0" iyy="0" iyz="0" izz="0.001" />
        </inertial>
    </link>
    <link name="effector_link">
        <visual>
            <geometry>
                <sphere radius="0.02" />
            </geometry>
            <material name="effector">
                <color rgba="0 1 0 0.2" />
            </material>
        </visual>
        <collision>
            <geometry>
                <sphere radius="0.02" />
            </geometry>
        </collision>
        <inertial>
            <mass value="0.001" />
            <inertia ixx="0" ixy="0" ixz="0" iyy="0" iyz="0" izz="0" />
        </inertial>
    </link>
    <!-- Arm actuator links -->
    <link name="upperarm_actuator_body_link">
        <visual>
            <origin rpy="0 0 0" xyz="0 0 0" />
            <geometry>
                <mesh filename="package://str1ker/description/models/UpperArmActuatorBody.stl" />
            </geometry>
            <material name="aluminum">
                <color rgba="1 1 1 1" />
            </material>
        </visual>
        <collision>
            <origin rpy="0 0 0" xyz="0 0 0" />
            <geometry>
                <mesh filename="package://str1ker/description/models/UpperArmActuatorBodyBoundingBox.stl" />
            </geometry>
        </collision>
        <inertial>
            <origin rpy="0 0 0" xyz="0 0 0" />
            <mass value="0.952544" />
            <inertia ixx="0.0084" ixy="0" ixz="0" iyy="0.0084" iyz="-0.0012" izz="0.0012" />
        </inertial>
    </link>
    <link name="upperarm_actuator_shaft_link">
        <visual>
            <origin rpy="0 0 0" xyz="0 0 0" />
            <geometry>
                <mesh filename="package://str1ker/description/models/UpperArmActuatorShaft.stl" />
            </geometry>
            <material name="aluminum">
                <color rgba="1 1 1 1" />
            </material>
        </visual>
        <collision>
            <origin rpy="0 0 0" xyz="0 0 0" />
            <geometry>
                <mesh filename="package://str1ker/description/models/UpperArmActuatorShaftBoundingBox.stl" />
            </geometry>
        </collision>
        <inertial>
            <mass value="0.070" />
            <origin rpy="0 0 0" xyz="0 0 0" />
            <inertia ixx="0.0001" ixy="0" ixz="0" iyy="0" iyz="0" izz="0" />
        </inertial>
    </link>
    <link name="forearm_actuator_body_link">
        <visual>
            <origin rpy="0 0 0" xyz="0 0 0" />
            <geometry>
                <mesh filename="package://str1ker/description/models/ForearmActuatorBody.stl" />
            </geometry>
            <material name="aluminum">
                <color rgba="1 1 1 1" />
            </material>
        </visual>
        <collision>
            <origin rpy="0 0 0" xyz="0 0 0" />
            <geometry>
                <mesh filename="package://str1ker/description/models/ForearmActuatorBodyBoundingBox.stl" />
            </geometry>
        </collision>
        <inertial>
            <mass value="0.199" />
            <origin rpy="0 0 0" xyz="0 0 0" />
            <inertia ixx="0.001" ixy="0" ixz="0" iyy="0" iyz="0" izz="0.001" />
        </inertial>
    </link>
    <link name="forearm_actuator_shaft_link">
        <visual>
            <origin rpy="0 0 0" xyz="0 0 0" />
            <geometry>
                <mesh filename="package://str1ker/description/models/ForearmActuatorShaft.stl" />
            </geometry>
            <material name="aluminum">
                <color rgba="1 1 1 1" />
            </material>
        </visual>
        <collision>
            <origin rpy="0 0 0" xyz="0 0 0" />
            <geometry>
                <mesh filename="package://str1ker/description/models/ForearmActuatorShaftBoundingBox.stl" />
            </geometry>
        </collision>
        <inertial>
            <mass value="0.113" />
            <origin rpy="0 0 0" xyz="0 0 0" />
            <inertia ixx="0.001" ixy="0" ixz="0" iyy="0" iyz="0" izz="0.001" />
        </inertial>
    </link>
    <link name="forearm_actuator_connector_link">
        <visual>
            <origin rpy="0 0 0" xyz="0 0 0" />
            <geometry>
                <mesh filename="package://str1ker/description/models/ForearmActuatorConnector.stl" />
            </geometry>
            <material name="aluminum">
                <color rgba="1 1 1 1" />
            </material>
        </visual>
        <collision>
            <origin rpy="0 0 0" xyz="0 0 0" />
            <geometry>
                <mesh filename="package://str1ker/description/models/ForearmActuatorConnectorBoundingBox.stl" />
            </geometry>
        </collision>
        <inertial>
            <mass value="0.013" />
            <origin rpy="0 0 0" xyz="0 0 0" />
            <inertia ixx="0" ixy="0" ixz="0" iyy="0" iyz="0" izz="0" />
        </inertial>
    </link>
    <!-- Arm joints -->
    <joint name="mount" type="revolute">
        <origin rpy="0 0 0" xyz="0 0 0" />
        <axis xyz="0 0 1" />
        <parent link="base_link" />
        <child link="shoulder_link" />
        <limit effort="100" velocity="1.0" lower="-1.4929" upper="1.4929" />
        <dynamics damping="0.7" friction="1.4" />
    </joint>
    <joint name="shoulder" type="revolute">
        <origin rpy="0 0 0" xyz="0 -0.013 0.11518" />
        <axis xyz="1 0 0" />
        <parent link="shoulder_link" />
        <child link="upperarm_link" />
        <limit effort="100" velocity="1.0" lower="0.404676" upper="0.813453" />
        <dynamics damping="0.7" friction="1.4" />
        <mimic joint="upperarm_actuator" multiplier="7.640691589" offset="0.817273346" />
    </joint>
    <joint name="elbow" type="revolute">
        <origin rpy="0 0 0" xyz="0 0.4173 0" />
        <axis xyz="1 0 0" />
        <parent link="upperarm_link" />
        <child link="forearm_link" />
        <limit effort="100" velocity="1.0" lower="-1.93302196" upper="-1.123992" />
        <dynamics damping="0.7" friction="1.4" />
        <mimic joint="forearm_actuator" multiplier="15.925786614" offset="-1.123992" />
    </joint>
    <joint name="effector" type="fixed">
        <origin rpy="0 0 0" xyz="-0.02 0.66 0.25" />
        <parent link="forearm_link" />
        <child link="effector_link" />
    </joint>
    <joint name="wrist" type="revolute">
        <origin rpy="0 0 0" xyz="-0.009 0.48059393086 0" />
        <axis xyz="1 0 0" />
        <parent link="forearm_link" />
        <child link="drumstick_link" />
        <limit effort="100" velocity="1.0" lower="1.0" upper="1.02" />
        <dynamics damping="0.7" friction="1.4" />
        <mimic joint="solenoid" multiplier="-6.8966" offset="1.0069" />
    </joint>
    <joint name="upperarm_actuator_mount" type="revolute">
        <origin rpy="0 0 0" xyz="0 0.101045 -0.0504975" />
        <axis xyz="1 0 0" />
        <parent link="shoulder_link" />
        <child link="upperarm_actuator_body_link" />
        <limit effort="100" velocity="1.0" lower="-0.1" upper="0.1" />
        <dynamics damping="0.7" friction="1.4" />
        <mimic joint="upperarm_actuator" multiplier="0.9" offset="-0.01" />
    </joint>
    <joint name="upperarm_actuator" type="prismatic">
        <origin rpy="0 0 0" xyz="0 -0.002 0.153" />
        <axis xyz="0 0 1" />
        <parent link="upperarm_actuator_body_link" />
        <child link="upperarm_actuator_shaft_link" />
        <limit effort="100" velocity="0.0508" lower="-0.054" upper="-0.0005" />
        <dynamics damping="0.7" friction="1.4" />
    </joint>
    <joint name="forearm_actuator_mount" type="revolute">
        <origin rpy="0 0 0" xyz="0 0.130 -0.034" />
        <axis xyz="1 0 0" />
        <parent link="upperarm_link" />
        <child link="forearm_actuator_body_link" />
        <limit effort="100" velocity="1.0" lower="-0.146607" upper="-0.118682" />
        <dynamics damping="0.7" friction="1.4" />
        <mimic joint="forearm_actuator" multiplier="-2.5" offset="-0.146602" />
    </joint>
    <joint name="forearm_actuator" type="prismatic">
        <origin rpy="0 0 0" xyz="0 0.210 0" />
        <axis xyz="0 1 0" />
        <parent link="forearm_actuator_body_link" />
        <child link="forearm_actuator_shaft_link" />
        <limit effort="100" velocity="0.0109982" lower="-0.0508" upper="0" />
        <dynamics damping="0.7" friction="1.4" />
    </joint>
    <joint name="forearm_actuator_connector" type="revolute">
        <origin rpy="0 0 0" xyz="0 0.0605718 0.004" />
        <axis xyz="1 0 0" />
        <parent link="forearm_link" />
        <child link="forearm_actuator_connector_link" />
        <limit effort="100" velocity="1.0" lower="1.5137" upper="1.5444" />
        <dynamics damping="0.7" friction="1.4" />
        <mimic joint="forearm_actuator" multiplier="0.604330709" offset="1.5444" />
    </joint>
    <joint name="solenoid_mount" type="revolute">
        <origin rpy="0 0 0" xyz="0.013 0.355 -0.031" />
        <axis xyz="1 0 0" />
        <parent link="forearm_link" />
        <child link="solenoid_mount_link" />
        <limit effort="100" velocity="1.0" lower="1.25" upper="1.9" />
        <dynamics damping="0.7" friction="1.4" />
    </joint>
    <joint name="solenoid" type="prismatic">
        <origin rpy="0 0 0" xyz="0 0 0" />
        <axis xyz="0 0 1" />
        <parent link="solenoid_mount_link" />
        <child link="solenoid_shaft_link" />
        <limit effort="100" velocity="1.0" lower="-0.0019" upper="0.001" />
        <dynamics damping="0.7" friction="1.4" />
    </joint>
    <!-- Arm transmissions -->
    <transmission name="trans_mount">
        <type>transmission_interface/SimpleTransmission</type>
        <joint name="mount">
            <hardwareInterface>hardware_interface/VelocityJointInterface</hardwareInterface>
        </joint>
        <actuator name="mount_motor">
            <hardwareInterface>hardware_interface/VelocityJointInterface</hardwareInterface>
            <mechanicalReduction>188</mechanicalReduction>
        </actuator>
    </transmission>
    <transmission name="trans_shoulder">
        <type>transmission_interface/SimpleTransmission</type>
        <joint name="upperarm_actuator">
            <hardwareInterface>hardware_interface/VelocityJointInterface</hardwareInterface>
        </joint>
        <actuator name="upperarm_linear">
            <hardwareInterface>hardware_interface/VelocityJointInterface</hardwareInterface>
            <mechanicalReduction>5</mechanicalReduction>
        </actuator>
    </transmission>
    <transmission name="trans_elbow">
        <type>transmission_interface/SimpleTransmission</type>
        <joint name="forearm_actuator">
            <hardwareInterface>hardware_interface/VelocityJointInterface</hardwareInterface>
        </joint>
        <actuator name="forearm_linear">
            <hardwareInterface>hardware_interface/VelocityJointInterface</hardwareInterface>
            <mechanicalReduction>49</mechanicalReduction>
        </actuator>
    </transmission>
    <gazebo>
        <plugin name="gazebo_ros_control">
            <robotNamespace>/</robotNamespace>
        </plugin>
    </gazebo>
    <transmission name="trans_upperarm_actuator_mount">
        <type>transmission_interface/SimpleTransmission</type>
        <joint name="upperarm_actuator_mount">
            <hardwareInterface>hardware_interface/EffortJointInterface</hardwareInterface>
        </joint>
        <actuator name="upperarm_actuator_mount_motor">
            <hardwareInterface>hardware_interface/EffortJointInterface</hardwareInterface>
            <mechanicalReduction>1</mechanicalReduction>
        </actuator>
    </transmission>
    <transmission name="trans_shoulder">
        <type>transmission_interface/SimpleTransmission</type>
        <joint name="shoulder">
            <hardwareInterface>hardware_interface/EffortJointInterface</hardwareInterface>
        </joint>
        <actuator name="shoulder_motor">
            <hardwareInterface>hardware_interface/EffortJointInterface</hardwareInterface>
            <mechanicalReduction>1</mechanicalReduction>
        </actuator>
    </transmission>
    <transmission name="trans_elbow">
        <type>transmission_interface/SimpleTransmission</type>
        <joint name="elbow">
            <hardwareInterface>hardware_interface/EffortJointInterface</hardwareInterface>
        </joint>
        <actuator name="elbow_motor">
            <hardwareInterface>hardware_interface/EffortJointInterface</hardwareInterface>
            <mechanicalReduction>1</mechanicalReduction>
        </actuator>
    </transmission>
    <transmission name="trans_wrist">
        <type>transmission_interface/SimpleTransmission</type>
        <joint name="wrist">
            <hardwareInterface>hardware_interface/EffortJointInterface</hardwareInterface>
        </joint>
        <actuator name="wrist_motor">
            <hardwareInterface>hardware_interface/EffortJointInterface</hardwareInterface>
            <mechanicalReduction>1</mechanicalReduction>
        </actuator>
    </transmission>
    <transmission name="trans_forearm_actuator_mount">
        <type>transmission_interface/SimpleTransmission</type>
        <joint name="forearm_actuator_mount">
            <hardwareInterface>hardware_interface/EffortJointInterface</hardwareInterface>
        </joint>
        <actuator name="forearm_actuator_mount_motor">
            <hardwareInterface>hardware_interface/EffortJointInterface</hardwareInterface>
            <mechanicalReduction>1</mechanicalReduction>
        </actuator>
    </transmission>
    <transmission name="trans_forearm_actuator_connector">
        <type>transmission_interface/SimpleTransmission</type>
        <joint name="forearm_actuator_connector">
            <hardwareInterface>hardware_interface/EffortJointInterface</hardwareInterface>
        </joint>
        <actuator name="forearm_actuator_connector_motor">
            <hardwareInterface>hardware_interface/EffortJointInterface</hardwareInterface>
            <mechanicalReduction>1</mechanicalReduction>
        </actuator>
    </transmission>
    <transmission name="trans_solenoid_mount">
        <type>transmission_interface/SimpleTransmission</type>
        <joint name="solenoid_mount">
            <hardwareInterface>hardware_interface/EffortJointInterface</hardwareInterface>
        </joint>
        <actuator name="solenoid_mount_motor">
            <hardwareInterface>hardware_interface/EffortJointInterface</hardwareInterface>
            <mechanicalReduction>1</mechanicalReduction>
        </actuator>
    </transmission>
    <transmission name="trans_solenoid">
        <type>transmission_interface/SimpleTransmission</type>
        <joint name="solenoid">
            <hardwareInterface>hardware_interface/VelocityJointInterface</hardwareInterface>
        </joint>
        <actuator name="solenoid_motor">
            <hardwareInterface>hardware_interface/VelocityJointInterface</hardwareInterface>
            <mechanicalReduction>1</mechanicalReduction>
        </actuator>
    </transmission>
</robot>

